Workbook

Sheet Samenvatting
A1: Onderdeel | B1: Mijn model (v1, lineair) | C1: Game (v2) | D1: Verschil
A2: Totaal ombuigingen en opbrengsten 2027 | B2: 130.617 | C2: 138.2122 | D2: =C2-B2
A3: Totaal uitgaven 2027 (excl. storting) | B3: 79.142 | C3: 113.48451 | D3: =C3-B3
A4: Saldo 2027 = storting reserve | B4: 51.475 | C4: 24.727693 | D4: =C4-B4
A5: Saldo 2028 | B5: 65.083 | C5: 60.521469 | D5: =C5-B5
A6: Saldo 2029 | B6: 79.039 | C6: 75.014639 | D6: =C6-B6
A7: Saldo 2030 | B7: 92.995 | C7: 88.26174 | D7: =C7-B7
A9: Bron: Ontwerpbegroting 2027 gemeente Groningen; rekenmodel Begrotingsgame VVD Groningen (scenario midden), stand 31-10-2026.
A10: Het oorspronkelijke xlsx was niet aangeleverd; "mijn model" is overgenomen uit de tabellen van Tegenbegroting_VVD_Groningen_2027_v1.docx.
A11: Grootste oorzaken: kettingeffecten (subsidies opzeggen −13,4; Wmo-contracten −10,3; frictiekosten ambtenaren −10,9 eenmalig;
A12: gemeenschappelijke regelingen −2,7 in 2027-2028; preventie → jeugdzorg/Wmo vanaf 2028) en drie programma's die in de game besparingen zijn i.p.v. uitgaven (+11,8).

Sheet Posten
A1: Post (zoals in v2) | B1: Tabel | C1: S/I | D1: Game-id(s) | E1: Kettingeffect | F1: % (schuif) | G1: Basis netto 2027 (mln) | H1: Mijn bedrag 2027 (lineair, v1) | I1: Game 2027 | J1: Verschil (game − v1) | K1: Game 2028 | L1: Game 2029 | M1: Game 2030 | N1: Oorzaak verschil
A2: Besparing overhead 20% | B2: Ombuiging | C2: S | D2: h1 | F2: 20 | G2: 131.5 | H2: 26.3 | I2: 26.3 | J2: =I2-H2 | K2: 26.3 | L2: 26.3 | M2: 26.3
A3: Besparingen op het ambtenarenapparaat 15% (oplopend) | B3: Ombuiging | C3: S | D3: k_apparaat_15 | F3: 15 | H3: 13.423 | I3: 13.423 | J3: =I3-H3 | K3: 26.846 | L3: 40.269 | M3: 53.692 | N3: Bedragen gelijk (25/50/75/100%); de game rekent daarnaast eenmalige frictiekosten (zie org_frictie).
A4: Taakstelling cultuur, instellingen en subsidies 40% | B4: Ombuiging | C4: S | D4: c2 | F4: 40 | G4: 29 | H4: 11.6 | I4: 11.6 | J4: =I4-H4 | K4: 11.6 | L4: 11.6 | M4: 11.6
A5: Wmo 15% | B5: Ombuiging | C5: S | D5: z3 | F5: 15 | G5: 68.8 | H5: 10.32 | I5: 10.32 | J5: =I5-H5 | K5: 10.32 | L5: 10.32 | M5: 10.32
A6: Taakstelling WIJ-teams 20% | B6: Ombuiging | C6: S | D6: z4 | F6: 20 | G6: 46.3 | H6: 9.26 | I6: 9.26 | J6: =I6-H6 | K6: 9.26 | L6: 9.26 | M6: 9.26
A7: Schrappen basisbanen 100% | B7: Ombuiging | C7: S | D7: s6 | F7: 100 | G7: 6.7 | H7: 6.7 | I7: 6.7 | J7: =I7-H7 | K7: 6.7 | L7: 6.7 | M7: 6.7
A8: Klimaat- en energiebeleid (CDOKE) 60% | B8: Ombuiging | C8: S | D8: w12 | F8: 60 | G8: 10.9 | H8: 6.54 | I8: 6.54 | J8: =I8-H8 | K8: 6.54 | L8: 6.54 | M8: 6.54
A9: Taakstelling armoede- en minimaregelingen 40% | B9: Ombuiging | C9: S | D9: s10 | F9: 40 | G9: 13.9 | H9: 5.56 | I9: 5.56 | J9: =I9-H9 | K9: 5.56 | L9: 5.56 | M9: 5.56
A10: Stadsschouwburg en Oosterpoort 40% | B10: Ombuiging | C10: S | D10: c1 | F10: 40 | G10: 10.7 | H10: 4.28 | I10: 4.28 | J10: =I10-H10 | K10: 4.28 | L10: 4.28 | M10: 4.28
A11: Sociale samenhang in wijken 45% | B11: Ombuiging | C11: S | D11: z9 | F11: 45 | G11: 7.1 | H11: 3.195 | I11: 3.195 | J11: =I11-H11 | K11: 3.195 | L11: 3.195 | M11: 3.195
A12: Taakstelling individuele inkomenstoeslag 75% | B12: Ombuiging | C12: S | D12: s12 | F12: 75 | G12: 4.2 | H12: 3.15 | I12: 3.15 | J12: =I12-H12 | K12: 3.15 | L12: 3.15 | M12: 3.15
A13: Gezondheid (GGD) 20% | B13: Ombuiging | C13: S | D13: z6 | F13: 20 | G13: 12 | H13: 2.4 | I13: 2.4 | J13: =I13-H13 | K13: 2.4 | L13: 2.4 | M13: 2.4
A14: Concernposten 40% | B14: Ombuiging | C14: S | D14: g7 | F14: 40 | G14: 5.9 | H14: 2.36 | I14: 2.36 | J14: =I14-H14 | K14: 2.36 | L14: 2.36 | M14: 2.36
A15: Welzijnsinstellingen en buurthuizen 25% | B15: Ombuiging | C15: S | D15: z8 | F15: 25 | G15: 8.454 | H15: 2.125 | I15: 2.1135 | J15: =I15-H15 | K15: 2.1135 | L15: 2.1135 | M15: 2.1135 | N15: Basis: game netto 8,454 (lasten 8,7 − baten 0,246); lineair rekende met 8,5.
A16: Wijkvernieuwing 30% | B16: Ombuiging | C16: S | D16: g4 | F16: 30 | G16: 6.15 | H16: 1.86 | I16: 1.845 | J16: =I16-H16 | K16: 1.845 | L16: 1.845 | M16: 1.845 | N16: Basis: game 6,15; lineair 6,2.
A17: Kettingeffect: lager parkeertarief trekt meer bezoekers | B17: Ombuiging | C17: S | D17: ec_parkeren_elasticiteit | E17: ja | H17: 0 | I17: 1.742352 | J17: =I17-H17 | K17: 1.742352 | L17: 1.742352 | M17: 1.742352 | N17: Nieuwe regel: kettingeffect uit de game (niet in het lineaire model).
A18: Natuur- en duurzaamheidseducatie 100% | B18: Ombuiging | C18: S | D18: d6 | F18: 100 | G18: 1.4 | H18: 1.4 | I18: 1.4 | J18: =I18-H18 | K18: 1.4 | L18: 1.4 | M18: 1.4
A19: Bijzondere bijstand 25% | B19: Ombuiging | C19: S | D19: s11 | F19: 25 | G19: 5.44 | H19: 1.35 | I19: 1.36 | J19: =I19-H19 | K19: 1.36 | L19: 1.36 | M19: 1.36 | N19: Basis: game netto 5,44 (5,9 − 0,46); lineair 5,4.
A20: Ambtenaren mobiliteit 40% | B20: Ombuiging | C20: S | D20: m11 | F20: 40 | G20: 3.3 | H20: 1.32 | I20: 1.32 | J20: =I20-H20 | K20: 1.32 | L20: 1.32 | M20: 1.32
A21: Ambtenaren wonen 25% | B21: Ombuiging | C21: S | D21: w4 | F21: 25 | G21: 4.9 | H21: 1.225 | I21: 1.225 | J21: =I21-H21 | K21: 1.225 | L21: 1.225 | M21: 1.225
A22: Diversiteit en inclusie 85% | B22: Ombuiging | C22: S | D22: z10 | F22: 85 | G22: 1.4 | H22: 1.19 | I22: 1.19 | J22: =I22-H22 | K22: 1.19 | L22: 1.19 | M22: 1.19
A23: Cultuur- en evenementenbeleid 10% | B23: Ombuiging | C23: S | D23: c3 | F23: 10 | G23: 10 | H23: 1 | I23: 1 | J23: =I23-H23 | K23: 1 | L23: 1 | M23: 1
A24: Extra geld energietransitie 40% | B24: Ombuiging | C24: S | D24: w7 | F24: 40 | G24: 2.3 | H24: 0.92 | I24: 0.92 | J24: =I24-H24 | K24: 0.92 | L24: 0.92 | M24: 0.92
A25: Uitvoering mobiliteitsvisie 55% | B25: Ombuiging | C25: S | D25: m4 | F25: 55 | G25: 1.56 | H25: 0.88 | I25: 0.858 | J25: =I25-H25 | K25: 0.858 | L25: 0.858 | M25: 0.858 | N25: Basis: game 1,56; lineair 1,6.
A26: Cultureel vastgoed 25% | B26: Ombuiging | C26: S | D26: c5 | F26: 25 | G26: 3.4 | H26: 0.85 | I26: 0.85 | J26: =I26-H26 | K26: 0.85 | L26: 0.85 | M26: 0.85
A27: Strategisch bezit en grondzaken 35% | B27: Ombuiging | C27: S | D27: e7 | F27: 35 | G27: 2.4 | H27: 0.84 | I27: 0.84 | J27: =I27-H27 | K27: 0.84 | L27: 0.84 | M27: 0.84
A28: Samenwerkingsverbanden 30% | B28: Ombuiging | C28: S | D28: g5 | F28: 30 | G28: 2.1 | H28: 0.63 | I28: 0.63 | J28: =I28-H28 | K28: 0.63 | L28: 0.63 | M28: 0.63
A29: Minder wethouders 24% | B29: Ombuiging | C29: S | D29: g1 | F29: 24 | G29: 2.4 | H29: 0.576 | I29: 0.576 | J29: =I29-H29 | K29: 0.576 | L29: 0.576 | M29: 0.576
A30: Energiesubsidies 55% | B30: Ombuiging | C30: S | D30: w6 | F30: 55 | G30: 1 | H30: 0.55 | I30: 0.55 | J30: =I30-H30 | K30: 0.55 | L30: 0.55 | M30: 0.55
A31: Minder bouwregels: welstandsvrij bouwen | B31: Ombuiging | C31: S | D31: k_minder_bouwregels | H31: 0.49 | I31: 0.49 | J31: =I31-H31 | K31: 0.49 | L31: 0.49 | M31: 0.49
A32: Kettingeffect: meer begeleiding naar werk, minder bijstand | B32: Ombuiging | C32: S | D32: wia_reintegratie | E32: ja | H32: 0 | I32: 0.48195 | J32: =I32-H32 | K32: 1.12455 | L32: 1.6065 | M32: 1.6065 | N32: Nieuwe regel: kettingeffect uit de game (niet in het lineaire model).
A33: Regio Groningen-Assen 25% | B33: Ombuiging | C33: S | D33: e9 | F33: 25 | G33: 1.1 | H33: 0.275 | I33: 0.275 | J33: =I33-H33 | K33: 0.275 | L33: 0.275 | M33: 0.275
A34: Geo en data 15% | B34: Ombuiging | C34: S | D34: o8 | F34: 15 | G34: 1.8 | H34: 0.27 | I34: 0.27 | J34: =I34-H34 | K34: 0.27 | L34: 0.27 | M34: 0.27
A35: Aanpak Oosterhamrikzone 100% | B35: Ombuiging | C35: S | D35: m9 | F35: 100 | G35: 0.25 | H35: 0.3 | I35: 0.25 | J35: =I35-H35 | K35: 0.25 | L35: 0.25 | M35: 0.25 | N35: Basis: game 0,25; lineair 0,3.
A36: Opvang vluchtelingen en asielzoekers 16,7% | B36: Ombuiging | C36: S | D36: z11 | F36: 16,7 | G36: 1.2 | H36: 0.2 | I36: 0.2004 | J36: =I36-H36 | K36: 0.2004 | L36: 0.2004 | M36: 0.2004 | N36: Afronding (0,2004).
A37: Parkeercontrole 20% | B37: Ombuiging | C37: S | D37: m2 | F37: 20 | G37: 1 | H37: 0.2 | I37: 0.2 | J37: =I37-H37 | K37: 0.2 | L37: 0.2 | M37: 0.2
A38: Elektrisch maken gemeenteauto’s uitstellen | B38: Ombuiging | C38: S | D38: p_emissieloos_wagenpark | H38: 0.172 | I38: 0.172 | J38: =I38-H38 | K38: 0.172 | L38: 0.172 | M38: 0.172
A39: Geen geld voor Campus Camera | B39: Ombuiging | C39: S | D39: p_campus_camera | H39: 0.1 | I39: 0.1 | J39: =I39-H39 | K39: 0.1 | L39: 0.1 | M39: 0.1
A40: Stoppen met budget internationale solidariteit | B40: Ombuiging | C40: S | D40: p_internationale_solidariteit | H40: 0.05 | I40: 0.05 | J40: =I40-H40 | K40: 0.05 | L40: 0.05 | M40: 0.05
...

Sheet Meerjarig
A1: Omschrijving | B1: 2027 | C1: 2028 | D1: 2029 | E1: 2030 | F1: Mijn 2027 (v1) | G1: Mijn 2028 | H1: Mijn 2029 | I1: Mijn 2030
A2: Ombuigingen en opbrengsten, structureel | B2: =SUMIFS(Posten!I:I,Posten!$B:$B,"Ombuiging",Posten!$C:$C,"S") | C2: =SUMIFS(Posten!K:K,Posten!$B:$B,"Ombuiging",Posten!$C:$C,"S") | D2: =SUMIFS(Posten!L:L,Posten!$B:$B,"Ombuiging",Posten!$C:$C,"S") | E2: =SUMIFS(Posten!M:M,Posten!$B:$B,"Ombuiging",Posten!$C:$C,"S") | F2: 123.861 | G2: 137.817 | H2: 151.773 | I2: 165.728
A3: Ombuigingen en opbrengsten, incidenteel | B3: =SUMIFS(Posten!I:I,Posten!$B:$B,"Ombuiging",Posten!$C:$C,"I") | C3: =SUMIFS(Posten!K:K,Posten!$B:$B,"Ombuiging",Posten!$C:$C,"I") | D3: =SUMIFS(Posten!L:L,Posten!$B:$B,"Ombuiging",Posten!$C:$C,"I") | E3: =SUMIFS(Posten!M:M,Posten!$B:$B,"Ombuiging",Posten!$C:$C,"I") | F3: 6.756 | G3: 0 | H3: 0 | I3: 0
A4: Uitgaven, structureel (als negatief bedrag) | B4: =SUMIFS(Posten!I:I,Posten!$B:$B,"Uitgave",Posten!$C:$C,"S") | C4: =SUMIFS(Posten!K:K,Posten!$B:$B,"Uitgave",Posten!$C:$C,"S") | D4: =SUMIFS(Posten!L:L,Posten!$B:$B,"Uitgave",Posten!$C:$C,"S") | E4: =SUMIFS(Posten!M:M,Posten!$B:$B,"Uitgave",Posten!$C:$C,"S") | F4: -72.733 | G4: -72.733 | H4: -72.733 | I4: -72.733
A5: Uitgaven, incidenteel excl. storting (negatief) | B5: =SUMIFS(Posten!I:I,Posten!$B:$B,"Uitgave",Posten!$C:$C,"I") | C5: =SUMIFS(Posten!K:K,Posten!$B:$B,"Uitgave",Posten!$C:$C,"I") | D5: =SUMIFS(Posten!L:L,Posten!$B:$B,"Uitgave",Posten!$C:$C,"I") | E5: =SUMIFS(Posten!M:M,Posten!$B:$B,"Uitgave",Posten!$C:$C,"I") | F5: -6.409 | G5: 0 | H5: 0 | I5: 0
A6: Saldo | B6: =SUM(B2:B5) | C6: =SUM(C2:C5) | D6: =SUM(D2:D5) | E6: =SUM(E2:E5) | F6: =SUM(F2:F5) | G6: =SUM(G2:G5) | H6: =SUM(H2:H5) | I6: =SUM(I2:I5)
A7: waarvan structureel | B7: =B2+B4 | C7: =C2+C4 | D7: =D2+D4 | E7: =E2+E4 | F7: =F2+F4 | G7: =G2+G4 | H7: =H2+H4 | I7: =I2+I4
A8: waarvan incidenteel | B8: =B3+B5 | C8: =C3+C5 | D8: =D3+D5 | E8: =E3+E5 | F8: =F3+F5 | G8: =G3+G5 | H8: =H3+H5 | I8: =I3+I5
A9: Controle: saldo volgens de game (structureel) | B9: 23.960293 | C9: 60.521469 | D9: 75.014639 | E9: 88.26174
A10: Controle: saldo volgens de game (incidenteel) | B10: 0.7674 | C10: 0 | D10: 0 | E10: 0
A11: Cumulatief saldo | B11: =B6 | C11: =B11+C6 | D11: =C11+D6 | E11: =D11+E6 | F11: =F6 | G11: =F11+G6 | H11: =G11+H6 | I11: =H11+I6

Sheet Eenmalig en overig
A1: Post | B1: Tabel | C1: Mijn 2027 (v1) | D1: Game 2027 | E1: Toelichting
A2: Stoppen met opvang ongedocumenteerden | B2: Ombuiging | C2: 5.6 | D2: 5.6
A3: Stoppen met het preventiefonds jeugd | B3: Ombuiging | C3: -4.509 | D3: 4.509 | E3: Teken: in de game is dit STOPPEN met het programma (eenmalige besparing), v1 boekte het als uitgave.
A4: Stoppen met het werkprogramma bijstand | B4: Ombuiging | C4: -1.05 | D4: 1.05 | E4: Teken: in de game stoppen met het programma (besparing), v1 als uitgave.
A5: Route Arbeid+ niet uitbreiden | B5: Ombuiging | C5: -0.35 | D5: 0.35 | E5: Teken: in de game uitbreiding niet doorzetten (besparing), v1 als uitgave.
A6: Schrappen cultuurprogramma Niemeyer | B6: Ombuiging | C6: 0.25 | D6: 0.25
A7: Stoppen uitvoering plan van aanpak diversiteit | B7: Ombuiging | C7: 0.205 | D7: 0.205
A8: Organisatiekosten Energiebedrijf Groningen | B8: Ombuiging | C8: 0.201 | D8: 0.201
A9: Geen gemeentegeld voor dierenartskosten | B9: Ombuiging | C9: 0.05 | D9: 0.05
A10: Kettingeffect: frictiekosten minder ambtenaren | B10: Uitgave | C10: 0 | D10: -10.9476
A11: Kosten onderzoek SMR | B11: Uitgave | C11: -0.5 | D11: -0.5
A12: Verbeteren financiële positie (storting reserve) | B12: Uitgave | C12: -51.475 | D12: -24.727693 | E12: Sluitpost = saldo 2027 (S + I).
